<mujoco model="lite6">
  <default>
    <default class="robot">
      <default class="motor">
        <joint stiffness="590" damping="100"/>  <!-- Increased stiffness -->
        <motor ctrlrange="-10 10" ctrllimited="true" forcerange="-500000 500000"/>
      </default>
      <default class="visual">
        <geom material="visualgeom" contype="0" conaffinity="0" group="2" />
      </default>
      <default class="collision">
        <geom material="collision_material" condim="3" contype="0" conaffinity="1" priority="1" group="1" solref="0.005 1" friction="1 0.01 0.01" />
        <equality solimp="0.99 0.999 1e-05" solref="0.005 1" />
      </default>
    </default>
  </default>

  <compiler angle="radian" />


  <option timestep="0.002" gravity="0 0 -9.81"/>
  
  
  <asset>
    <material name="default_material" rgba="0.7 0.7 0.7 1" />
    <material name="collision_material" rgba="1.0 0.28 0.1 0.9" />
    <mesh name="xarm_link6_mesh" file="/home/nikola/code/alignit/alignit/mujoco_menagerie/ufactory_lite6/assets/visual/link6.stl"/>
    <mesh name="base_mesh" file="/home/nikola/code/alignit/alignit/mujoco_menagerie/ufactory_lite6/assets/visual/link_base.stl"/>
    <mesh name="link1_mesh" file="/home/nikola/code/alignit/alignit/mujoco_menagerie/ufactory_lite6/assets/visual/link1.stl"/>
    <mesh name="link2_mesh" file="/home/nikola/code/alignit/alignit/mujoco_menagerie/ufactory_lite6/assets/visual/link2.stl"/>
    <mesh name="link3_mesh" file="/home/nikola/code/alignit/alignit/mujoco_menagerie/ufactory_lite6/assets/visual/link3.stl"/>
    <mesh name="link4_mesh" file="/home/nikola/code/alignit/alignit/mujoco_menagerie/ufactory_lite6/assets/visual/link4.stl"/>
    <mesh name="link5_mesh" file="/home/nikola/code/alignit/alignit/mujoco_menagerie/ufactory_lite6/assets/visual/link5.stl"/>
  </asset>

  <worldbody>
    <body name="link_base" pos="0.00000000 0.00000000 0.00000000" quat="1 0 0 0" childclass="robot">
    <geom type="mesh" mesh="base_mesh" rgba="0.6 0.6 0.6 1"/>
      <inertial pos="0 0 0" mass="2.5" diaginertia="0.01 0.01 0.01"/>
      <body name="link1" pos="0 0 0.2435" quat="1.0 0.0 0.0 0.0">
        <geom type="mesh" mesh="link1_mesh" rgba="0.6 0.6 0.6 1"/>
        <joint name="joint1" type="hinge" ref="0.0" class="motor" range="-6.28319 6.28319" axis="0 0 1" />
        <inertial pos="0 0 0" quat="1.0 0.0 0.0 0.0" mass="2.0" diaginertia="1e-05 1e-05 1e-05" />
        <body name="link2" pos="0 0 0" quat="0.5000037354821706 -0.49999840251375804 -0.5000019278969003 -0.4999959340704164">
        <geom type="mesh" mesh="link2_mesh" rgba="0.6 0.6 0.6 1"/>
          <joint name="joint2" type="hinge" ref="0.0" class="motor" range="-2.61799 2.61799" axis="0.000001 0 1" />
          <inertial pos="0 0 0" quat="1.0 0.0 0.0 0.0" mass="1.8" diaginertia="1e-05 1e-05 1e-05" />
          <body name="link3" pos="0.2002 0 0" quat="2.7059462988343167e-06 0.7071051289519305 0.7071084334069488 2.705958944305917e-06">
            <geom type="mesh" mesh="link3_mesh" rgba="0.6 0.6 0.6 1"/>
            <joint name="joint3" type="hinge" ref="0.0" class="motor" range="-0.061087 5.23599" axis="0 -0.000001 1" />
            <inertial pos="0 0 0" quat="1.0 0.0 0.0 0.0" mass="1.2" diaginertia="1e-05 1e-05 1e-05" />
            <body name="link4" pos="0.087 -0.22761 0" quat="0.7071054825112363 0.7071080798594735 0.0 0.0">
            <geom type="mesh" mesh="link4_mesh" rgba="0.6 0.6 0.6 1"/>
              <joint name="joint4" type="hinge" ref="0.0" class="motor" range="-6.28319 6.28319" axis="0 0 1" />
              <inertial pos="0 0 0" quat="1.0 0.0 0.0 0.0" mass="0.7" diaginertia="1e-05 1e-05 1e-05" />
              <body name="link5" pos="0 0 0" quat="0.7071054825112363 0.7071080798594735 0.0 0.0">
              <geom type="mesh" mesh="link1_mesh" rgba="0.6 0.6 0.6 1"/>
                <joint name="joint5" type="hinge" ref="0.0" class="motor" range="-2.1642 2.1642" axis="0 0 1" />
                <inertial pos="0 0 0" quat="1.0 0.0 0.0 0.0" mass="0.2" diaginertia="1e-05 1e-05 1e-05" />
                <body name="link6" pos="0 0.0625 0" quat="0.7071054825112363 -0.7071080798594735 0.0 0.0">
                  <geom type="mesh" mesh="xarm_link6_mesh" rgba="0.6 0.6 0.6 1"/>
                  <joint name="joint6" type="hinge" ref="0.0" class="motor" range="-6.28319 6.28319" axis="0 0 1" />
                    <inertial pos="0 0 0" mass="0.1" diaginertia="0.001 0.001 0.001"/> <site name="gripper_site" pos="0 0 0.1" size="0.01 0.01 0.01" rgba="1 0 0 1"/>
                </body>
              </body>
            </body>
          </body>
        </body>
      </body>
      <site name="link_base_site" pos="0 0 0" quat="1 0 0 0" />
      <camera name="front_camera" mode="track" fovy="90.0" quat="4.329780281177467e-17 4.329780281177466e-17 0.7071067811865475 0.7071067811865476" pos="0.0 2.0 0.5" />
      <camera name="side_camera" mode="track" fovy="90.0" quat="-0.5 -0.4999999999999999 0.5 0.5000000000000001" pos="-2.0 0.0 0.5" />
    </body>
  </worldbody>

  <actuator>
    <motor name="joint1_ctrl" joint="joint1" class="motor" />
    <motor name="joint2_ctrl" joint="joint2" class="motor" />
    <motor name="joint3_ctrl" joint="joint3" class="motor" />
    <motor name="joint4_ctrl" joint="joint4" class="motor" />
    <motor name="joint5_ctrl" joint="joint5" class="motor" />
    <motor name="joint6_ctrl" joint="joint6" class="motor" />
  </actuator>

  <sensor>
    <framepos name="link_base_site_pos" objtype="site" objname="link_base_site" />
    <framequat name="link_base_site_quat" objtype="site" objname="link_base_site" />
    <framelinvel name="link_base_site_linvel" objtype="site" objname="link_base_site" />
    <frameangvel name="link_base_site_angvel" objtype="site" objname="link_base_site" />
    <velocimeter name="link_base_site_vel" site="link_base_site" />
  </sensor>
</mujoco>